[rank: 0] Global seed set to 0
/projects/dali/spack/var/spack/environments/dali/.spack-env/view/lib/python3.10/site-packages/lightning/fabric/plugins/environments/slurm.py:165: PossibleUserWarning: The `srun` command is available on your system but is not used. HINT: If your intention is to run Lightning on SLURM, prepend your python command with `srun` like so: srun python train.py config_file=conf/india_fields.yaml module.m ...
  rank_zero_warn(
GPU available: True (cuda), used: True
TPU available: False, using: 0 TPU cores
IPU available: False, using: 0 IPUs
HPU available: False, using: 0 HPUs
/projects/dali/spack/var/spack/environments/dali/.spack-env/view/lib/python3.10/site-packages/lightning/fabric/plugins/environments/slurm.py:165: PossibleUserWarning: The `srun` command is available on your system but is not used. HINT: If your intention is to run Lightning on SLURM, prepend your python command with `srun` like so: srun python train.py config_file=conf/india_fields.yaml module.m ...
  rank_zero_warn(
You are using a CUDA device ('NVIDIA A100 80GB PCIe') that has Tensor Cores. To properly utilize them, you should set `torch.set_float32_matmul_precision('medium' | 'high')` which will trade-off precision for performance. For more details, read https://pytorch.org/docs/stable/generated/torch.set_float32_matmul_precision.html#torch.set_float32_matmul_precision
/projects/dali/spack/var/spack/environments/dali/.spack-env/view/lib/python3.10/site-packages/lightning/pytorch/callbacks/model_checkpoint.py:612: UserWarning: Checkpoint directory /scratch.local/yichia3/india_fields/output/india_fields_unet_resnet18_0.0001_ce_0.1_False_0 exists and is not empty.
  rank_zero_warn(f"Checkpoint directory {dirpath} exists and is not empty.")
LOCAL_RANK: 0 - CUDA_VISIBLE_DEVICES: [0]

  | Name          | Type             | Params
---------------------------------------------------
0 | model         | Unet             | 14.4 M
1 | loss          | CrossEntropyLoss | 0     
2 | train_metrics | MetricCollection | 0     
3 | val_metrics   | MetricCollection | 0     
4 | test_metrics  | MetricCollection | 0     
---------------------------------------------------
3.2 M     Trainable params
11.2 M    Non-trainable params
14.4 M    Total params
57.439    Total estimated model params size (MB)
WARNING! The experiment directory, /scratch.local/yichia3/india_fields/output/india_fields_unet_resnet18_0.0001_ce_0.1_False_0, already exists, we might overwrite data in it!
Sanity Checking: 0it [00:00, ?it/s]Traceback (most recent call last):
  File "/home/yichia3/india_fields/torchgeo/train.py", line 156, in <module>
    main(conf)
  File "/home/yichia3/india_fields/torchgeo/train.py", line 129, in main
    trainer.fit(model=task, datamodule=datamodule)
  File "/projects/dali/spack/var/spack/environments/dali/.spack-env/view/lib/python3.10/site-packages/lightning/pytorch/trainer/trainer.py", line 520, in fit
    call._call_and_handle_interrupt(
  File "/projects/dali/spack/var/spack/environments/dali/.spack-env/view/lib/python3.10/site-packages/lightning/pytorch/trainer/call.py", line 44, in _call_and_handle_interrupt
    return trainer_fn(*args, **kwargs)
  File "/projects/dali/spack/var/spack/environments/dali/.spack-env/view/lib/python3.10/site-packages/lightning/pytorch/trainer/trainer.py", line 559, in _fit_impl
    self._run(model, ckpt_path=ckpt_path)
  File "/projects/dali/spack/var/spack/environments/dali/.spack-env/view/lib/python3.10/site-packages/lightning/pytorch/trainer/trainer.py", line 935, in _run
    results = self._run_stage()
  File "/projects/dali/spack/var/spack/environments/dali/.spack-env/view/lib/python3.10/site-packages/lightning/pytorch/trainer/trainer.py", line 976, in _run_stage
    self._run_sanity_check()
  File "/projects/dali/spack/var/spack/environments/dali/.spack-env/view/lib/python3.10/site-packages/lightning/pytorch/trainer/trainer.py", line 1005, in _run_sanity_check
    val_loop.run()
  File "/projects/dali/spack/var/spack/environments/dali/.spack-env/view/lib/python3.10/site-packages/lightning/pytorch/loops/utilities.py", line 177, in _decorator
    return loop_run(self, *args, **kwargs)
  File "/projects/dali/spack/var/spack/environments/dali/.spack-env/view/lib/python3.10/site-packages/lightning/pytorch/loops/evaluation_loop.py", line 98, in run
    self.setup_data()
  File "/projects/dali/spack/var/spack/environments/dali/.spack-env/view/lib/python3.10/site-packages/lightning/pytorch/loops/evaluation_loop.py", line 150, in setup_data
    dataloaders = _request_dataloader(source)
  File "/projects/dali/spack/var/spack/environments/dali/.spack-env/view/lib/python3.10/site-packages/lightning/pytorch/trainer/connectors/data_connector.py", line 328, in _request_dataloader
    return data_source.dataloader()
  File "/projects/dali/spack/var/spack/environments/dali/.spack-env/view/lib/python3.10/site-packages/lightning/pytorch/trainer/connectors/data_connector.py", line 298, in dataloader
    return call._call_lightning_datamodule_hook(self.instance.trainer, self.name)
  File "/projects/dali/spack/var/spack/environments/dali/.spack-env/view/lib/python3.10/site-packages/lightning/pytorch/trainer/call.py", line 162, in _call_lightning_datamodule_hook
    return fn(*args, **kwargs)
  File "/home/yichia3/india_fields/torchgeo/torchgeo/datamodules/geo.py", line 281, in val_dataloader
    raise MisconfigurationException(msg)
torchgeo.datamodules.utils.MisconfigurationException: IndiaFieldsDataModule.setup does not define a 'val_dataset'
                                   python train.py config_file=conf/india_fields.yaml module.model=unet module.backbone=resnet18 module.learning_rate=0.0001 module.loss=ce module.weight_decay=0.1 module.weights=False program.experiment_name=india_fields_unet_resnet18_0.0001_ce_0.1_False_0 program.seed=0 trainer.devices=[0]
